Workbook

Sheet ფართები
A1: lisi saxli - 12
B3: TariRi | C3: 45590 | D3: $ | E3: 2.71
A5: # | B5: sarTuli | C5: samS. farTi | D5: sasarg. farTi | E5: %
A6: 1 | B6: 2 | C6: 3 | D6: 4 | E6: 5
A7: 1 | B7: saZirkveli | C7: =(21.1*15.2)*3 -> 962.16 | D7: 603.6 | E7: =D7/C7 -> 0.62733849
A8: 2 | B8: 1 | C8: =(21.1*15.2)*3 -> 962.16 | D8: 649.1 | E8: =D8/C8 -> 0.67462792
A9: 3 | B9: 2 | C9: =(21.1*15.2)*3+8.3+9.9+0.63+0.63+8.3+9.9+0.63+0.63+8.28+8.28+7.1+7.1 -> 1031.84 | D9: 788.9 | E9: =D9/C9 -> 0.76455652
A10: 4 | B10: 3 | C10: =(21.1*15.2)*3+8.3+9.9+0.63+0.63+8.3+9.9+0.63+0.63+8.28+8.28+7.1+7.1 -> 1031.84 | D10: 788.9 | E10: =D10/C10 -> 0.76455652
A11: 5 | B11: 4 | C11: =(21.1*15.2)*3+8.3+9.9+0.63+0.63+8.3+9.9+0.63+0.63+8.28+8.28+7.1+7.1 -> 1031.84 | D11: 788.9 | E11: =D11/C11 -> 0.76455652
A12: 6 | B12: saxuravi | C12: =(21.1*15.2)*3+8.3+9.9+8.3+9.9+8.28+8.28+7.1+7.1 -> 1029.32
B13: jami | C13: =SUM(C7:C12) -> 6049.16 | D13: =SUM(D7:D12) -> 3619.4 | E13: =D13/C13 -> 0.59833101
D17: 1ლ/m2 | E17: 1$/m2
A18: qvabuli | B18: =ბიუჯეტი!K25 -> 177948.8 | D18: =B18/C13 -> 29.417108 | E18: =D18/E3 -> 10.855022
A19: Savi karkasi | B19: =ბიუჯეტი!K59 -> 2684765 | D19: =B19/C13 -> 443.82444 | E19: =D19/E3 -> 163.77286
A20: TeTri karkasi | B20: =ბიუჯეტი!K502 -> 3971935.4 | D20: =B20/C13 -> 656.60941 | E20: =D20/E3 -> 242.29129
D21: =SUM(D18:D20) -> 1129.851 | E21: =SUM(E18:E20) -> 416.91917
B25: 9 10 | D25: 1ლ/m2 | E25: 1$/m2
A26: qvabuli | B26: 212951.22 | D26: 35.108543 | E26: 12.787203
A27: Savi karkasi | B27: 2687533 | D27: 443.08442 | E27: 161.37981
A28: TeTri karkasi | B28: 3887861.7 | D28: 640.97853 | E28: 233.45663
D29: 1119.1715 | E29: 407.62365

Sheet ბიუჯეტი
A1: q. TbilisSi, lisi
A2: sacxovrebeli saxlis winaswari xarjTaRricxva
A3: saxli #12
A4: xarjTaRricxva
A6: # | B6: samuSaos dasaxeleba | C6: gan/ba | D6: raod. | E6: masala, erT | F6: masala, sul | G6: xelf, erT | H6: xelf, sul | I6: moms. erT | J6: moms, sul | K6: jami
A7: 1 | B7: 2 | C7: 3 | D7: 4 | E7: 5 | F7: 6 | G7: 7 | H7: 8 | I7: 9 | J7: 10 | K7: 11
B8: qvabulis samuSao
A9: 1 | B9: qvabulis mowyoba | C9: m2 | D9: =SUM(D10:D13) -> 4909.6034 | E9: =SUM(F10:F13)/D9 -> 0 | F9: =D9*E9 -> 0 | G9: 0 | H9: =D9*G9 -> 0 | I9: 18.7 | J9: =I9*D9 -> 91809.584 | K9: =F9+H9+J9 -> 91809.584
B10: qvabulis amoReba | C10: m3 | D10: =(20*69)*2.1*1.3 -> 3767.4 | E10: 0 | F10: 0 | G10: 0 | H10: =D10*G10 -> 0 | I10: 0 | J10: =I10*D10 -> 0 | K10: =F10+H10+J10 -> 0
B11: liftis Saxtis ormos amoReba | C11: m3 | D11: =(4.7*4.5*2*1.3)*3 -> 164.97 | E11: 0 | F11: =D11*E11 -> 0 | G11: 0 | H11: =D11*G11 -> 0 | I11: 0 | J11: =I11*D11 -> 0 | K11: =F11+H11+J11 -> 0
B12: amwis adgilis mosworeba | C12: m3 | D12: =(47*6*0.7+39*8*0.65)*1.3 -> 520.26 | E12: 0 | F12: =D12*E12 -> 0 | G12: 0 | H12: =D12*G12 -> 0 | I12: 0 | J12: =I12*D12 -> 0 | K12: =F12+H12+J12 -> 0
B13: svetis ormos amoReba | C13: m3 | D13: =((2*2*2.5*3)+(2*2*1.4*2)+(2*2*1*3)+(2.7*2*2.2*2)+(2.7*2*3)+(4.7*2*1.8)+(2*2*1*4)+(2*2*2.3*2)+(4.7*2*1.5)+(12.2*2.7*2.7)+(2*2*3.4)+(2*2*1.4*3)+(2*2*2.2*2)+(2*2*3.1*3)+(4.7*2*2))*1.3 -> 456.9734 | E13: 0 | F13: =D13*E13 -> 0 | G13: 0 | H13: =D13*G13 -> 0 | I13: 0 | J13: =I13*D13 -> 0 | K13: =F13+H13+J13 -> 0
A14: 2 | B14: kodaliT muSaoba | C14: dRe | D14: 20 | E14: 0 | F14: =D14*E14 -> 0 | H14: =D14*G14 -> 0 | I14: =1400/1.18 -> 1186.4407 | J14: =I14*D14 -> 23728.814 | K14: =F14+H14+J14 -> 23728.814
B15: jami | F15: =F14+F9 -> 0 | H15: =H14+H9 -> 0 | J15: =J14+J9 -> 115538.4 | K15: =K14+K9 -> 115538.4
B16: zednadebi xarji | C16: 0.074 | K16: =K15*C16 -> 8549.8414
B17: jami | K17: =SUM(K15:K16) -> 124088.24
B18: yalibi | C18: 0.03 | K18: =K17*C18 -> 3722.6472
B19: jami | K19: =SUM(K17:K18) -> 127810.89
B20: teqnika | C20: 0.035 | K20: =K19*C20 -> 4473.381
B21: jami | K21: =SUM(K19:K20) -> 132284.27
B22: mogeba | C22: 0.14 | K22: =K21*C22 -> 18519.797
B23: jami | K23: =SUM(K21:K22) -> 150804.06
B24: dRg | C24: 0.18 | K24: =K23*C24 -> 27144.732
B25: mTliani | K25: =SUM(K23:K24) -> 177948.8
A27: # | B27: samuSaos dasaxeleba | C27: gan/ba | D27: raod. | E27: masala, erT | F27: masala, sul | G27: xelf, erT | H27: xelf, sul | I27: moms. erT | J27: moms, sul | K27: jami
A28: 1 | B28: 2 | C28: 3 | D28: 4 | E28: 5 | F28: 6 | G28: 7 | H28: 8 | I28: 9 | J28: 10 | K28: 11
B29: konstruqciuli nawili
A30: 1 | B30: rkinabetonis karkasi | C30: m2 | D30: =D31 -> 7525.247 | E30: =SUM(F31:F42)/D30 -> 139.28843 | F30: =D30*E30 -> 1048179.9 | G30: =SUM(H31:H42)/D30 -> 64.96989 | H30: =D30*G30 -> 488914.47 | I30: =SUM(J31:J42)/D30 -> 6.9729993 | J30: =I30*D30 -> 52473.542 | K30: =F30+H30+J30 -> 1589567.9
B31: karkasis mowyoba | C31: m2 | D31: =სამუშაო!I111 -> 7525.247 | F31: 0 | G31: =ხელფასი!D3 -> 63.75 | H31: =D31*G31 -> 479734.5 | K31: =F31+H31+J31 -> 479734.5
B32: betoni b-7.5 | C32: m3 | D32: =60*1.02 -> 61.2 | E32: =მასალა!D5 -> 173.72881 | F32: =D32*E32 -> 10632.203 | H32: =D32*G32 -> 0 | I32: =1000/1.18 -> 847.45763 | J32: =I32*6 -> 5084.7458 | K32: =F32+H32+J32 -> 15716.949
B33: betoni b-25 | C33: m3 | D33: =1870*1.02 -> 1907.4 | E33: =მასალა!D6 -> 219.49153 | F33: =D33*E33 -> 418658.14 | H33: =D33*G33 -> 0 | K33: =F33+H33+J33 -> 418658.14
B34: Sveleris mowyoba | C34: grZ.m | D34: =321.6*1.1194 -> 359.99904 | E34: =მასალა!D9 -> 98.305085 | F34: =D34*E34 -> 35389.736 | G34: =ხელფასი!D42 -> 25.5 | H34: =D34*G34 -> 9179.9755 | I34: 8 | J34: =I34*D34 -> 2879.9923 | K34: =F34+H34+J34 -> 47449.704
B35: liTonis furclis mowyoba | C35: grZ.m | D35: =(3.1*8+3.7*8+2.6*6)*1.1 -> 77 | E35: 0 | F35: =D35*E35 -> 0 | G35: 0 | H35: =D35*G35 -> 0 | I35: =მომსახურება!D27 -> 177.9661 | J35: =I35*D35+1500 -> 15203.39 | K35: =F35+H35+J35 -> 15203.39
B36: armatura a240 | C36: t | D36: 0 | E36: =მასალა!$D$7 -> 1906.1864 | F36: =D36*E36 -> 0 | H36: =D36*G36 -> 0 | K36: =F36+H36+J36 -> 0
B37: armatura a500 | C37: t | D37: =239.843388295*1.05 -> 251.83556 | E37: =მასალა!$D$7 -> 1906.1864 | F37: =D37*E37 -> 480045.53 | H37: =D37*G37 -> 0 | K37: =F37+H37+J37 -> 480045.53
B38: Savi karkasis damxmare masala | C38: m2 | D38: =$D$31 -> 7525.247 | E38: =SUMIFS(მასალა!D3:D112,მასალა!B3:B112,ბიუჯეტი!B38) -> 10.169492 | F38: =D38*E38 -> 76527.936 | H38: =D38*G38 -> 0 | K38: =F38+H38+J38 -> 76527.936
B39: betonis Semowmeba kubikebiT | C39: cali | D39: =D33*0.15 -> 286.11 | E39: 0 | F39: =D39*E39 -> 0 | H39: =D39*G39 -> 0 | I39: =მომსახურება!D26 -> 42.372881 | J39: =I39*D39 -> 12123.305 | K39: =F39+H39+J39 -> 12123.305
B40: geodeziuri momsaxureba | C40: cali | D40: 27 | E40: 0 | F40: =D40*E40 -> 0 | H40: =D40*G40 -> 0 | I40: =მომსახურება!D25 -> 466.10169 | J40: =I40*D40 -> 12584.746 | K40: =F40+H40+J40 -> 12584.746
B41: RorRi 10*20 | C41: m3 | D41: =64.5*15.8*0.12*1.02+30 -> 154.73784 | E41: =მასალა!D4 -> 38.135593 | F41: =D41*E41 -> 5901.0193 | H41: =G41*D41 -> 0 | I41: =7/1.18 -> 5.9322034 | J41: =I41*D41 -> 917.93634 | K41: =F41+H41+J41 -> 6818.9557
B42: inertuli masala | C42: m3 | D42: =(65.5+16.5)*1.5*3.2*1.3+65.5*0.85*1.5*1.3 -> 620.24625 | E42: =მასალა!D3 -> 33.898305 | F42: =D42*E42 -> 21025.297 | H42: =G42*D42 -> 0 | I42: =7/1.18 -> 5.9322034 | J42: =I42*D42 -> 3679.4269 | K42: =F42+H42+J42 -> 24704.724
...

Sheet სამუშაო
A1: 20 iani bloki
A2: # | B2: niS.\ | C2: sarTuli | D2: fasadi | E2: sadarbazo | F2: binebis gamyofi | G2: ზღუდარი | H2: სარტყელი | I2: jami | J2: vada
A3: 1 | B3: 2 | C3: 3 | D3: 4 | E3: 5 | F3: 6 | G3: 7 | H3: 8 | I3: 9 | J3: 10
A4: 1 | B4: -2.3 | C4: 1 | D4: 0 | E4: =((16.4+16.4+2+2+7+7.6+2.5+5.17+5.17+2.52)*2.32)*3 -> 464.6496 | F4: =((2+7+7+7.4+2+4.8+5.1)*2.32)*3 -> 245.688 | G4: =1.5*3 -> 4.5 | H4: =2.5*3 -> 7.5 | I4: =SUM(D4:H4) -> 722.3376
A5: 2 | B5: 0 | C5: 2 | D5: =(3.3+2.4+1.5+4.2)*2.97*3+(6.5+6.5+7+7+7+7+3.6+6.5+2.7)*2.6*3 -> 521.214 | E5: =((7+2.9+4.2+8+7+1.6+1.4+1.8+5.6+2.65+1.2)*2.97)*2+(2.65+2.9+7+1.2+7+1.8+1.8+7+8+4+1.6)*2.97 -> 391.0005 | F5: =((5+6.7+0.84)*2.97)*2+((6.5+6.7+0.85)*2.97) -> 116.2161 | G5: =12*1.5 -> 18 | H5: =(4.2+1.5+2.4+3.3)*3 -> 34.2 | I5: =SUM(D5:H5)-I15-D56+E56+F56*2.2 -> 932.2106
A6: 3 | B6: 3.2 | C6: 3 | D6: =(((7+7+2.7+3.1+3.6+5.1+7+3.4+3.4)*2.6)+((3.4+0.8+4+3.6+1.3+3.6+1.3)*2.97))*2+(6.5+6.5+6.5+7+7+7+7+2.7+2.7)*2.6+(4.2+1.6+4.2+1.6)*2.97 -> 498.872 | E6: =((7+6.5+1.6+2.9+5.35+1.3+1.5)*2.97)*2+(7+7+6.5+1.3+1.5+2.9)*2.97 -> 233.145 | F6: =((2.7+7.6+7)*2.97)*2+((6.5+6.5+7.8)*2.97) -> 164.538 | G6: =13*1.5 -> 19.5 | H6: =3.6+3.6+4+3.4+3.2+2.3+3.6+3.6+4+3.4+3.2+2.3+4.2+4.2 -> 48.6 | I6: =SUM(D6:H6)-I17-D57+G57*2.2+25 -> 832.945
A7: 3 | B7: 6.4 | C7: 3 | D7: =(((7+7+2.7+3.1+3.6+5.1+7+3.4+3.4)*2.6)+((3.4+0.8+4+3.6+1.3+3.6+1.3)*2.97))*2+(6.5+6.5+6.5+7+7+7+7+2.7+2.7)*2.6+(4.2+1.6+4.2+1.6)*2.97 -> 498.872 | E7: =((7+6.5+1.6+2.9+5.35+1.3+1.5)*2.97)*2+(7+7+6.5+1.3+1.5+2.9)*2.97 -> 233.145 | F7: =((2.7+7.6+7)*2.97)*2+((6.5+6.5+7.8)*2.97) -> 164.538 | G7: =13*1.5 -> 19.5 | H7: =3.6+3.6+4+3.4+3.2+2.3+3.6+3.6+4+3.4+3.2+2.3+4.2+4.2 -> 48.6 | I7: =SUM(D7:H7)-I18-D58+G58*2.2+25 -> 832.945
A8: 4 | B8: 9.6 | C8: 4 | D8: =(((7+7+2.7+3.1+3.6+5.1+7+3.4+3.4)*2.6)+((3.4+0.8+4+3.6+1.3+3.6+1.3)*2.97))*2+(6.5+6.5+6.5+7+7+7+7+2.7+2.7)*2.6+(4.2+1.6+4.2+1.6)*2.97 -> 498.872 | E8: =((7+6.5+1.6+2.9+5.35+1.3+1.5)*2.97)*2+(7+7+6.5+1.3+1.5+2.9)*2.97 -> 233.145 | F8: =((2.7+7.6+7)*2.97)*2+((6.5+6.5+7.8)*2.97) -> 164.538 | G8: =13*1.5 -> 19.5 | H8: =3.6+3.6+4+3.4+3.2+2.3+3.6+3.6+4+3.4+3.2+2.3+4.2+4.2 -> 48.6 | I8: =SUM(D8:H8)-I18-D59+G59*2.2+25 -> 832.945
E9: =(20.6-7.5)+(17-3.5)+14.8+10+8+2.5+3+11+11+5 -> 91.9 | I9: =SUM(I4:I8) -> 4153.3832 | J9: =SUM(J4:J8) -> 0
E10: =E9*2.32*3 -> 639.624
A11: m/plastmasi
A12: # | B12: niS.\ | C12: sarTuli | E12: =(14.4+5.5+13.4+10.5+7.6+2.2+2.4+2.4+1.8+1.8+2.25+1.55+3+8.65+9.6)*2.97*3 -> 775.6155 | I12: jami | J12: vada
A13: 1 | B13: 2 | C13: 3 | D13: 4 | E13: 5 | F13: 6 | G13: 7 | H13: 8 | I13: 9 | J13: 10
A14: 1 | B14: -2.3 | C14: 1 | D14: =1.6*0.6*15 -> 14.4 | I14: =SUM(D14:H14) -> 14.4
A15: 2 | B15: 0 | C15: 2 | D15: =(1.6*1.6)*5+(1*1.6)*2+(1.6*2.5)*24+(1*2.5)*3+(1.7*2.6)*6 -> 146.02 | I15: =SUM(D15:H15) -> 146.02
A16: 2 | B16: 3.2 | C16: 2 | D16: =(1.6*1.6)*6+(1*1.6)*2+(1.6*2.5)*16+(1*2.5)*2+(1.7*2.5)*4+(1.5*2.5)*6+(5.25*2.5)*2 -> 153.31 | I16: =SUM(D16:H16) -> 153.31
A17: 3 | B17: 6.4 | C17: 3 | D17: =(1.6*1.6)*6+(1*1.6)*2+(1.6*2.5)*16+(1*2.5)*2+(1.7*2.5)*4+(1.5*2.5)*6+(5.25*2.5)*2 -> 153.31 | I17: =SUM(D17:H17) -> 153.31
A18: 4 | B18: 9.6 | C18: 4 | D18: =(1.6*1.6)*6+(1*1.6)*2+(1.6*2.5)*16+(1*2.5)*2+(1.7*2.5)*4+(1.5*2.5)*6+(5.25*2.5)*2 -> 153.31 | I18: =SUM(D18:H18) -> 153.31
I19: =SUM(I14:I18) -> 620.35 | J19: =SUM(J14:J18) -> 0
A21: fasadi
A22: # | B22: niS.\ | C22: sarTuli | D22: aguri | E22: daTbuneba/Rebva | F22: ferdili | G22: betonis faqtura | H22: bazalti | I22: jami | J22: vada
A23: 1 | B23: 2 | C23: 3 | D23: 4 | E23: 5 | F23: 6 | G23: 7 | H23: 8 | I23: 9 | J23: 10
A24: 1 | B24: -2.3 | C24: 1 | D24: 0 | F24: 0 | H24: =1.6*15 -> 24 | I24: =SUM(D24:H24) -> 24
A25: 2 | B25: 0 | C25: 2 | D25: 894.5 | E25: =(1.8+3.1+2.2+1.3+4+0.9)*2.97*2+6.9*2.6*6+1.8+3.1+2.15+4+1.4+0.9*2.97 -> 201.765 | F25: =1.6*25+2.6*12+1*2+3.8*2+3*9 -> 107.8 | G25: 0 | H25: =1.6*5+1*2+1.7*6 -> 20.2 | I25: =SUM(D25:H25) -> 1224.265
A26: 3 | B26: 3.2 | C26: 3 | E26: =((0.7+3.3+1.2+0.7+3.3+1.2+3.9+2+4+1.6+0.4+0.8+3.4+0.8+3.1)*2+1.2+1.55+2.7+4.2+1.55+2.7)*2.97 -> 221.859 | F26: =(1.6*24+1.7*4+1*4+2.6*22+3.1*2+3.2*13)*3 -> 462.6 | H26: =1.5*6+1*2+1.6*6 -> 20.6 | I26: =SUM(D26:H26) -> 705.059 | K26: =87+144+87+25+28+51+51+29+25+131+45+131+57+6 -> 897
A27: 4 | B27: 6.4 | C27: 4 | E27: =((0.7+3.3+1.2+0.7+3.3+1.2+3.9+2+4+1.6+0.4+0.8+3.4+0.8+3.1)*2+1.2+1.55+2.7+4.2+1.55+2.7)*2.97 -> 221.859 | H27: =1.5*6+1*2+1.6*6 -> 20.6 | I27: =SUM(D27:H27) -> 242.459
A28: 5 | B28: 9.6 | C28: 5 | E28: =((0.7+3.3+1.2+0.7+3.3+1.2+3.9+2+4+1.6+0.4+0.8+3.4+0.8+3.1)*2+1.2+1.55+2.7+4.2+1.55+2.7)*2.97 -> 221.859 | H28: =1.5*6+1*2+1.6*6 -> 20.6 | I28: =SUM(D28:H28) -> 242.459
C29: 6 | F29: 6 | I29: =SUM(D29:H29) -> 6
I30: =SUM(I24:I29) -> 2444.242 | J30: =SUM(J25:J28) -> 0
A32: 10 iani bloki
A33: # | B33: niS.\ | C33: sarTuli | D33: sadabazo | E33: aivani | F33: sak.Saxta binebi | G33: sak.Saxta sadarbazo | H33: tualeti | I33: jami | J33: vada
A34: 1 | B34: 2 | C34: 3 | D34: 4 | E34: 5 | F34: 6 | G34: 7 | H34: 8 | I34: 9 | J34: 10
A35: 1 | B35: -2.3 | C35: 1 | D35: 0 | F35: 0 | G35: =1.9*3*2.32 -> 13.224 | H35: 0 | I35: =SUM(D35:H35) -> 13.224
A36: 2 | B36: 0 | C36: 2 | D36: 0 | E36: 0 | F36: =23.6*2.97 -> 70.092 | G36: =15.3*2.97 -> 45.441 | H36: 68.25 | I36: =SUM(D36:H36) -> 183.783
A37: 2 | B37: 3.2 | C37: 3 | D37: 0 | E37: 0 | F37: =31.8*2.98 -> 94.764 | G37: =15.3*2.97 -> 45.441 | H37: 68.25 | I37: =SUM(D37:H37) -> 208.455
A38: 3 | B38: 6.4 | C38: 4 | D38: 0 | E38: 0 | F38: =31.8*2.98 -> 94.764 | G38: =15.3*2.97 -> 45.441 | H38: 68.25 | I38: =SUM(D38:H38) -> 208.455
A39: 4 | B39: 9.6 | C39: 5 | D39: 0 | E39: 0 | F39: =31.8*2.98 -> 94.764 | G39: =15.3*2.97 -> 45.441 | H39: 68.25 | I39: =SUM(D39:H39) -> 208.455
I40: =SUM(I35:I39) -> 822.372 | J40: =SUM(J35:J39) -> 0
A42: sadarbazo
A43: # | B43: niS.\ | C43: sarTuli | D43: lesva | E43: SefiTvna | F43: Rebva | G43: liftis aguri | H43: mdf | I43: jami | J43: vada
...

Sheet მასალა
A1: # | B1: samuSaos dasaxeleba | C1: gan/ba | D1: masala, erT | E1: სახლი 9-10 | G1: სახლი 13
A2: 1 | B2: 2 | C2: 3 | D2: 5
B3: inertuli masala | C3: m3 | D3: =40/1.18 -> 33.898305 | E3: 33.898305 | F3: =D3-E3 -> 0 | G3: 33.898305 | H3: =D3-G3 -> 0
B4: RorRi 10*20 | C4: m3 | D4: =45/1.18 -> 38.135593 | E4: 38.135593 | F4: =D4-E4 -> 0 | G4: 38.135593 | H4: =D4-G4 -> 0
B5: betoni b-7.5 | C5: m3 | D5: =205/1.18 -> 173.72881 | E5: 173.72881 | F5: =D5-E5 -> 0 | G5: 173.72881 | H5: =D5-G5 -> 0
B6: betoni b-25 | C6: m3 | D6: =259/1.18 -> 219.49153 | E6: 219.49153 | F6: =D6-E6 -> 0 | G6: 219.49153 | H6: =D6-G6 -> 0
B7: armatura | C7: t | D7: =830*ფართები!E3/1.18 -> 1906.1864 | E7: 1931.2271 | F7: =D7-E7 -> -25.040678 | G7: 1931.2271 | H7: =D7-G7 -> -25.040678
B8: bloki 20-iani | C8: c | D8: =1.97/1.18 -> 1.6694915 | E8: 1.6694915 | F8: =D8-E8 -> 0 | G8: 1.6694915 | H8: =D8-G8 -> 0
B9: Sveleri 22 ni | C9: გრძ/მ | D9: =116/1.18 -> 98.305085 | E9: 98.305085 | F9: =D9-E9 -> 0 | G9: 98.305085 | H9: =D9-G9 -> 0
B10: qviSa | C10: m3 | D10: =70/1.18 -> 59.322034 | E10: 59.322034 | F10: =D10-E10 -> 0 | G10: 59.322034 | H10: =D10-G10 -> 0
B11: cementi m300 | C11: t | D11: =313.29/1.18 -> 265.5 | E11: 265.47458 | F11: =D11-E11 -> 0.025423729 | G11: 265.47458 | H11: =D11-G11 -> 0.025423729
B12: aguri dekoratiuli | C12: cali | D12: =0.95/1.18 -> 0.80508475 | E12: 0.80508475 | F12: =D12-E12 -> 0 | G12: 0.80508475 | H12: =D12-G12 -> 0
B13: bazalti | C13: m2 | D13: =78/1.18 -> 66.101695 | E13: 66.101695 | F13: =D13-E13 -> 0 | G13: 66.101695 | H13: =D13-G13 -> 0
B14: Savi qviSa | C14: m3 | D14: =70/1.18 -> 59.322034 | E14: 59.322034 | F14: =D14-E14 -> 0 | G14: 59.322034 | H14: =D14-G14 -> 0
B15: bazaltis fila 03 | C15: m2 | D15: =70/1.18 -> 59.322034 | E15: 59.322034 | F15: =D15-E15 -> 0 | G15: 59.322034 | H15: =D15-G15 -> 0
B16: bazaltis fila 02 | C16: m2 | D16: =40/1.18 -> 33.898305 | E16: 33.898305 | F16: =D16-E16 -> 0 | G16: 33.898305 | H16: =D16-G16 -> 0
B17: bazaltis fila 05 | C17: m2 | D17: =140/1.18 -> 118.64407 | E17: 118.64407 | F17: =D17-E17 -> 0 | G17: 118.64407 | H17: =D17-G17 -> 0
B18: saRebavi | C18: litri | D18: =14.4/1.18 -> 12.20339 | E18: 12.20339 | F18: =D18-E18 -> 0 | G18: 12.20339 | H18: =D18-G18 -> 0
B19: kibis safexuri | C19: ცალი | D19: =140/1.18 -> 118.64407 | E19: 118.64407 | F19: =D19-E19 -> 0 | G19: 118.64407 | H19: =D19-G19 -> 0
B20: webo/cementi | C20: c | D20: =13/1.18 -> 11.016949 | E20: 11.016949 | F20: =D20-E20 -> 0 | G20: 11.016949 | H20: =D20-G20 -> 0
B21: meTlaxis fila | C21: მ2 | D21: =45/1.18 -> 38.135593 | E21: 38.135593 | F21: =D21-E21 -> 0 | G21: 38.135593 | H21: =D21-G21 -> 0
B22: fiTxi | C22: c | D22: =16.5/1.18 -> 13.983051 | E22: 13.983051 | F22: =D22-E22 -> 0 | G22: 13.983051 | H22: =D22-G22 -> 0
B23: bloki 10-iani | C23: c | D23: =1.25/1.18 -> 1.059322 | E23: 1.059322 | F23: =D23-E23 -> 0 | G23: 1.059322 | H23: =D23-G23 -> 0
B24: Tunuqi | C24: m2 | D24: =23/1.18 -> 19.491525 | E24: 19.491525 | F24: =D24-E24 -> 0 | G24: 19.491525 | H24: =D24-G24 -> 0
B25: membrana | C25: m2 | D25: =4/1.18 -> 3.3898305 | E25: 3.3898305 | F25: =D25-E25 -> 0 | G25: 3.3898305 | H25: =D25-G25 -> 0
B26: xis masala | C26: m3 | D26: =850/1.18 -> 720.33898 | E26: 652.54237 | F26: =D26-E26 -> 67.79661 | G26: 652.54237 | H26: =D26-G26 -> 67.79661
B27: xis dasamuSavebeli xsnari | C27: ლ | D27: =3.8/1.18 -> 3.220339 | E27: 3.220339 | F27: =D27-E27 -> 0 | G27: 3.220339 | H27: =D27-G27 -> 0
B28: milkvadrati 60*80 | C28: grZ.m | D28: =14.6/1.18 -> 12.372881 | E28: 12.372881 | F28: =D28-E28 -> 0 | G28: 12.372881 | H28: =D28-G28 -> 0
B29: iqspiesi | C29: m3 | D29: =8/1.18 -> 6.779661 | E29: 6.779661 | F29: =D29-E29 -> 0 | G29: 6.779661 | H29: =D29-G29 -> 0
B30: milkvadrati 100*100 | C30: grZ.m | D30: =21/1.18 -> 17.79661 | E30: 17.79661 | F30: =D30-E30 -> 0 | G30: 17.79661 | H30: =D30-G30 -> 0
B31: cementi m400 | C31: t | D31: =358.72/1.18 -> 304 | E31: 303.98305 | F31: =D31-E31 -> 0.016949153 | G31: 303.98305 | H31: =D31-G31 -> 0.016949153
B32: T/muyaos fila | C32: c | D32: =14.9/1.18 -> 12.627119 | E32: 12.627119 | F32: =D32-E32 -> 0 | G32: 12.627119 | H32: =D32-G32 -> 0
B33: profili cd | C33: c | D33: =11.1/1.18 -> 9.4067797 | E33: 9.4067797 | F33: =D33-E33 -> 0 | G33: 9.4067797 | H33: =D33-G33 -> 0
B34: profili ud | C34: c | D34: =8.2/1.18 -> 6.9491525 | E34: 6.9491525 | F34: =D34-E34 -> 0 | G34: 6.9491525 | H34: =D34-G34 -> 0
B35: minabamba | C35: m2 | D35: =2.9/1.18 -> 2.4576271 | E35: 2.4576271 | F35: =D35-E35 -> 0 | G35: 2.4576271 | H35: =D35-G35 -> 0
B36: agrafi | C36: c | D36: =0.96/1.18 -> 0.81355932 | E36: 0.81355932 | F36: =D36-E36 -> 0 | G36: 0.81355932 | H36: =D36-G36 -> 0
B37: Surufi tn25 | C37: c | D37: =0.035/1.18 -> 0.029661017 | E37: 0.029661017 | F37: =D37-E37 -> 0 | G37: 0.029661017 | H37: =D37-G37 -> 0
B38: Surufi tn35 | C38: c | D38: =0.045/1.18 -> 0.038135593 | E38: 0.038135593 | F38: =D38-E38 -> 0 | G38: 0.038135593 | H38: =D38-G38 -> 0
B39: dubel Surufi k6 | C39: c | D39: =0.095/1.18 -> 0.080508475 | E39: 0.080508475 | F39: =D39-E39 -> 0 | G39: 0.080508475 | H39: =D39-G39 -> 0
B40: semiWka Surufi | C40: c | D40: =0.038/1.18 -> 0.03220339 | E40: 0.03220339 | F40: =D40-E40 -> 0 | G40: 0.03220339 | H40: =D40-G40 -> 0
...

Sheet მომსახურება
A1: # | B1: samuSaos dasaxeleba | C1: gan/ba | D1: Rirebuleba, erT
A2: 1 | B2: 2 | C2: 3 | D2: 5
B3: m/p kar-fanjara | C3: m2 | D3: =130*[2]ფართები!E2/1.18 -> 301.86441 | E3: 301.86441 | F3: =D3-E3 -> 0
B4: aluminis vitraJi | C4: m2 | D4: =160*ფართები!E3/1.18 -> 367.45763 | E4: 372.28475 | F4: =D4-E4 -> -4.8271186
B5: mdf-iT mowyoba | C5: m2 | D5: =230*1.27 -> 292.1 | E5: 292.1 | F5: =D5-E5 -> 0
B6: kar-fanjrebis izolacia | C6: grZ.m | D6: =18/1.18 -> 15.254237 | E6: 15.254237 | F6: =D6-E6 -> 0
B7: iatakebis moWimva | C7: m2 | D7: =14/1.18 -> 11.864407 | E7: 10.169492 | F7: =D7-E7 -> 1.6949153
B8: liTonis binis kari | C8: cali | D8: =1300/1.18 -> 1101.6949 | E8: 1101.6949 | F8: =D8-E8 -> 0
B9: სარდაფის kari | C9: cali | D9: =900/1.18 -> 762.71186 | E9: 762.71186 | F9: =D9-E9 -> 0
B10: saqvabis kari | C10: cali | D10: =1750/1.18 -> 1483.0508 | E10: 1483.0508 | F10: =D10-E10 -> 0
B11: liTonis sadarbazos kari | C11: cali | D11: =3600/1.18 -> 3050.8475 | E11: 3050.8475 | F11: =D11-E11 -> 0
B12: saxuravze gasasvleli gisosi | C12: cali | D12: =170/1.18 -> 144.0678 | E12: 144.0678 | F12: =D12-E12 -> 0
B13: liTonis kibis ujredis kari | C13: cali | D13: =1700/1.18 -> 1440.678 | E13: 1440.678 | F13: =D13-E13 -> 0
B14: liTonis aivnis moajiri | C14: grZ.m | D14: =260/1.18 -> 220.33898 | E14: 220.33898 | F14: =D14-E14 -> 0
B15: liTonis aivnis moajiri ცხაური | C15: მ2 | D15: =260/1.18 -> 220.33898 | E15: 220.33898 | F15: =D15-E15 -> 0
B16: liTonis kibis moajiri | C16: grZ.m | D16: =260/1.18 -> 220.33898 | E16: 220.33898 | F16: =D16-E16 -> 0
B17: liTonis kibis moajiri kedelze misamagrebeli | C17: grZ.m | D17: =85/1.18 -> 72.033898 | E17: 72.033898 | F17: =D17-E17 -> 0
B18: sakomunikacio liTonis kari xis dgarebiT | C18: cali | D18: =2000/1.18 -> 1694.9153 | E18: 1694.9153 | F18: =D18-E18 -> 0
B19: ezos gamyofi xis tixrebi | C19: cali | D19: =1500/1.18 -> 1271.1864 | E19: 1271.1864 | F19: =D19-E19 -> 0
B20: asaZromi kibe | C20: c | D20: =220/1.18 -> 186.44068 | E20: 186.44068 | F20: =D20-E20 -> 0
B21: lifti | C21: cali | D21: =(112425*[2]ფართები!E2/1.18)/2 -> 130527.33 | E21: 130527.33 | F21: =D21-E21 -> 0
B22: domofonis mowyoba | C22: bina | D22: =350/1.18 -> 296.61017 | E22: 296.61017 | F22: =D22-E22 -> 0
B23: internetis daqselva | C23: bina | D23: =160/1.18 -> 135.59322 | E23: 135.59322 | F23: =D23-E23 -> 0
B24: inertuli masalis tkepnis Semowmeba | C24: cali | D24: =50/1.18 -> 42.372881 | E24: 42.372881 | F24: =D24-E24 -> 0
B25: geodeziuri momsaxureba | C25: cali | D25: =550/1.18 -> 466.10169 | E25: 466.10169 | F25: =D25-E25 -> 0
B26: betonis kubikebis Semowmeba | C26: cali | D26: =50/1.18 -> 42.372881 | E26: 42.372881 | F26: =D26-E26 -> 0
B27: liTonis furclis mowyoba | C27: მ2 | D27: =210/1.18 -> 177.9661 | E27: 177.9661 | F27: =D27-E27 -> 0
B28: ინტერნეტის დაქსელვა | C28: მ2 | D28: =90/1.18 -> 76.271186 | E28: 76.271186 | F28: =D28-E28 -> 0
B29: samisamarTo saxanZro signalizaciis mowyoba | C29: სართული | D29: =5000/1.18 -> 4237.2881 | E29: 4237.2881 | F29: =D29-E29 -> 0
B30: saxanZro mildgarebis sistemis mowyoba | C30: სართული | D30: =1300/1.18 -> 1101.6949 | E30: 1101.6949 | F30: =D30-E30 -> 0
B31: saxanZro saventilacio danadgarebis mowyoba | C31: სართული | D31: =3400/1.18 -> 2881.3559 | E31: 2881.3559 | F31: =D31-E31 -> 0
B32: tenti | C32: ცალი | D32: =7667/1.18 -> 6497.4576 | E32: 419.49153 | F32: =D32-E32 -> 6077.9661
B33: wasasmeli hidroizolacia | C33: m2 | D33: =63/1.18 -> 53.389831 | E33: 53.389831 | F33: =D33-E33 -> 0

Sheet ხელფასი
A1: # | B1: samuSaos dasaxeleba | C1: gan/ba | D1: Rirebuleba, erT
A2: 1 | B2: 2 | C2: 3 | D2: 5
B3: რკინა ბეტონის მოწყობა | C3: მ2 | D3: =50*1.275 -> 63.75 | E3: 63.75 | F3: =D3-E3 -> 0
B4: ბლოკი | C4: მ2 | D4: =1.5*1.275*12.5 -> 23.90625 | E4: 23.90625 | F4: =D4-E4 -> 0
B5: ზღუდარი | C5: გრძ/მ | D5: =15*1.275 -> 19.125 | E5: 19.125 | F5: =D5-E5 -> 0
B6: სარტყელი | C6: გრძ/მ | D6: =40*1.275 -> 51 | E6: 44.625 | F6: =D6-E6 -> 6.375
B7: აგური | C7: მ2 | D7: =65*1.275 -> 82.875 | E7: 82.875 | F7: =D7-E7 -> 0
B8: aguris ferdili | C8: grZ.m | D8: =35*1.275 -> 44.625 | E8: 44.625 | F8: =D8-E8 -> 0
B9: aguris cxauris mowyoba | C9: მ2 | D9: =120*1.275 -> 153 | E9: 153 | F9: =D9-E9 -> 0
B10: bazaltis sacremlis mowyoba | C10: grZ.m | D10: =16*1.275 -> 20.4 | E10: 20.4 | F10: =D10-E10 -> 0
B11: kar-fanjris ferdilebis amovseba | C11: cali | D11: =5*1.275 -> 6.375 | E11: 6.375 | F11: =D11-E11 -> 0
B12: საცრემლის მოწყობა | C12: grZ.m | D12: =3*1.275 -> 3.825 | E12: 3.825 | F12: =D12-E12 -> 0
B13: saxuravze Tunuqis mowyoba | C13: m2 | D13: =(23+25)*1.275 -> 61.2 | E13: 61.2 | F13: =D13-E13 -> 0
B14: mwvane saxuravis mowyoba | C14: m2 | D14: =26.5*1.275 -> 33.7875 | E14: 33.7875 | F14: =D14-E14 -> 0
B15: k/granitis mowyoba | C15: m2 | D15: =30*1.275 -> 38.25 | E15: 38.25 | F15: =D15-E15 -> 0
B16: k/granitis plintusis mowyoba | C16: grZ.m | D16: =10*1.275 -> 12.75 | E16: 12.75 | F16: =D16-E16 -> 0
B17: bazaltis safexuris mowyoba | C17: cali | D17: =40*1.275 -> 51 | E17: 44.625 | F17: =D17-E17 -> 6.375
B18: T/muyaos kedlis mowyoba | C18: m2 | D18: =12*1.275 -> 15.3 | E18: 15.3 | F18: =D18-E18 -> 0
B19: T/muyaos tixris mowyoba | C19: m2 | D19: =16*1.275 -> 20.4 | E19: 20.4 | F19: =D19-E19 -> 0
B20: gaTfobis milebis daqselva | C20: bina | D20: =130*1.275 -> 165.75 | E20: 165.75 | F20: =D20-E20 -> 0
B21: kanalizaciis qselis mowyoba | C21: cali | D21: =25*1.275 -> 31.875 | E21: 31.875 | F21: =D21-E21 -> 0
B22: kanalizaciis qselis mowyoba binaSi | C22: cali | D22: =45*1.275 -> 57.375 | E22: 57.375 | F22: =D22-E22 -> 0
B23: ventilaciis qselis mowyoba | C23: cali | D23: =25*1.275 -> 31.875 | E23: 31.875 | F23: =D23-E23 -> 0
B24: eleqtroobis mowyoba | C24: cali | D24: =8*1.275 -> 10.2 | E24: 10.2 | F24: =D24-E24 -> 0
B25: aivnis sanaTis mowyoba | C25: cali | D25: =12*1.275 -> 15.3 | E25: 15.3 | F25: =D25-E25 -> 0
B26: sadarbazos sanaTis mowyoba | C26: cali | D26: =45*1.275 -> 57.375 | E26: 57.375 | F26: =D26-E26 -> 0
B27: Telasis kabelis mowyoba | C27: cali | D27: =45*1.275 -> 57.375 | E27: 57.375 | F27: =D27-E27 -> 0
B28: sadarbazos daqselva | C28: grZ.m | D28: =3*1.275 -> 3.825 | E28: 3.825 | F28: =D28-E28 -> 0
B29: wylis centraluri dgaris mowyoba | C29: grZ.m | D29: =20*1.275 -> 25.5 | E29: 25.5 | F29: =D29-E29 -> 0
B30: wylis daqselva binebSi | C30: cali | D30: =(110+40)*1.275 -> 191.25 | E30: 191.25 | F30: =D30-E30 -> 0
B31: kuTxovanis mowyoba | C31: grZ.m | D31: =10*1.275 -> 12.75 | E31: 12.75 | F31: =D31-E31 -> 0
B32: kedlis gaxvreta kondincionerisTvis | C32: cali | D32: =10*1.275 -> 12.75 | E32: 12.75 | F32: =D32-E32 -> 0
B33: Sida aivanze trapebis mowyoba | C33: cali | D33: =20*1.275 -> 25.5 | E33: 25.5 | F33: =D33-E33 -> 0
B34: fasadis daTfuneba | C34: m2 | D34: =45*1.275 -> 57.375 | E34: 57.375 | F34: =D34-E34 -> 0
B35: sadarbazos lesva | C35: m2 | D35: =18*1.275 -> 22.95 | E35: 22.95 | F35: =D35-E35 -> 0
B36: SefiTxvna | C36: m2 | D36: =15*1.275 -> 19.125 | E36: 19.125 | F36: =D36-E36 -> 0
B37: Rebva | C37: m2 | D37: =7*1.275 -> 8.925 | E37: 8.925 | F37: =D37-E37 -> 0
B38: შავად ლესვა | C38: m2 | D38: =15*1.275 -> 19.125 | E38: 19.125 | F38: =D38-E38 -> 0
B39: ეზოს სანიაღვრე ღარის მოწყობა | C39: გრძ/მ | D39: =50*1.275 -> 63.75 | E39: 63.75 | F39: =D39-E39 -> 0
B40: კიბის საფეხურის მოწყობა | C40: ცალი | D40: =40*1.275 -> 51 | E40: 51 | F40: =D40-E40 -> 0
...
