Workbook

Sheet ფართები
A1: lisi saxli - 9/10
B3: TariRi | C3: 45590 | D3: $ | E3: 2.7456
A5: # | B5: sarTuli | C5: samS. farTi | D5: sasarg. farTi | E5: %
A6: 1 | B6: 2 | C6: 3 | D6: 4 | E6: 5
A7: 1 | B7: saZirkveli | C7: =(20.7*15.2)*3 -> 943.92 | D7: 633.7 | E7: =D7/C7 -> 0.67134927
A8: 2 | B8: 1 | C8: =(20.7*15.2)*3+8.28+8.28+0.63+0.63+0.63+0.63+16.02+16.02+4.14+8.28 -> 1007.46 | D8: 626.81 | E8: =D8/C8 -> 0.62216862
A9: 3 | B9: 2 | C9: =(20.7*15.2)*3+8.28+8.28+0.63+0.63+0.63+0.63+16.02+16.02+4.14+8.28 -> 1007.46 | D9: 753.8 | E9: =D9/C9 -> 0.74821829
A10: 4 | B10: 3 | C10: =(20.7*15.2)*3+8.28+8.28+0.63+0.63+0.63+0.63+16.02+16.02+4.14+8.28 -> 1007.46 | D10: 753.8 | E10: =D10/C10 -> 0.74821829
A11: 5 | B11: 4 | C11: =(20.7*15.2)*3+8.28+8.28+0.63+0.63+0.63+0.63+16.02+16.02+4.14+8.28 -> 1007.46 | D11: 753.8 | E11: =D11/C11 -> 0.74821829
A12: 6 | B12: saxuravi | C12: =(20.7*15.2)*3+8.28+8.28+16.02+16.02+4.14+8.28 -> 1004.94
B13: jami | C13: =SUM(C7:C12) -> 5978.7 | D13: =SUM(D7:D12) -> 3521.91 | E13: =D13/C13 -> 0.58907622
D17: 1ლ/m2 | E17: 1$/m2
A18: qvabuli | B18: =ბიუჯეტი!K25 -> 212951.22 | D18: =B18/C13 -> 35.618315 | E18: =D18/E3 -> 12.972871
A19: Savi karkasi | B19: =ბიუჯეტი!K59 -> 2646955 | D19: =B19/C13 -> 442.73086 | E19: =D19/E3 -> 161.25104
A20: TeTri karkasi | B20: =ბიუჯეტი!K501 -> 3891303.9 | D20: =B20/C13 -> 650.86121 | E20: =D20/E3 -> 237.05609
D21: =SUM(D18:D20) -> 1129.2104 | E21: =SUM(E18:E20) -> 411.28001
A25: lisi 8 | D25: 1ლ/m2 | E25: 1$/m2
A26: qvabuli | B26: 170960.66 | D26: 37.68675 | E26: 13.80467
A27: Savi karkasi | B27: 1847670.4 | D27: 407.30241 | E27: 149.19502
A28: TeTri karkasi | B28: 2850672 | D28: 628.40515 | E28: 230.18504
D29: 1073.3943 | E29: 393.18473

Sheet ბიუჯეტი
A1: q. TbilisSi, lisi
A2: sacxovrebeli saxlis winaswari xarjTaRricxva
A3: saxli #10
A4: xarjTaRricxva
I5: 45969
A6: # | B6: samuSaos dasaxeleba | C6: gan/ba | D6: raod. | E6: masala, erT | F6: masala, sul | G6: xelf, erT | H6: xelf, sul | I6: moms. erT | J6: moms, sul | K6: jami
A7: 1 | B7: 2 | C7: 3 | D7: 4 | E7: 5 | F7: 6 | G7: 7 | H7: 8 | I7: 9 | J7: 10 | K7: 11
B8: qvabulis samuSao
A9: 1 | B9: qvabulis mowyoba | C9: m2 | D9: =SUM(D10:D13) -> 6124.9155 | E9: =SUM(F10:F13)/D9 -> 0 | F9: =D9*E9 -> 0 | G9: 0 | H9: =D9*G9 -> 0 | I9: 18.7 | J9: =I9*D9 -> 114535.92 | K9: =F9+H9+J9 -> 114535.92
B10: qvabulis amoReba | C10: m3 | D10: =20*68.5*2.3*1.3 -> 4096.3 | E10: 0 | F10: 0 | G10: 0 | H10: =D10*G10 -> 0 | I10: 0 | J10: =I10*D10 -> 0 | K10: =F10+H10+J10 -> 0
B11: kranis da armaturis adgilis amoReba | C11: m3 | D11: =70*15*1.5 -> 1575 | E11: 0 | F11: 0 | G11: 0 | H11: =D11*G11 -> 0 | I11: 0 | J11: =I11*D11 -> 0 | K11: =F11+H11+J11 -> 0
B12: liftis Saxtis ormos amoReba | C12: m3 | D12: =(4.7*4.5*1.5*1.3)*3 -> 123.7275 | E12: 0 | F12: =D12*E12 -> 0 | G12: 0 | H12: =D12*G12 -> 0 | I12: 0 | J12: =I12*D12 -> 0 | K12: =F12+H12+J12 -> 0
B13: svetis ormos amoReba | C13: m3 | D13: =((2.6*2*1.9*2)+(2.6*2*2.7*2)+(2.6*2*3.8*2)+(2*2*8*0.9)+(2*2*8*1.7)+(2*2*8*2.6))*1.3 -> 329.888 | E13: 0 | F13: =D13*E13 -> 0 | G13: 0 | H13: =D13*G13 -> 0 | I13: 0 | J13: =I13*D13 -> 0 | K13: =F13+H13+J13 -> 0
A14: 2 | B14: kodaliT muSaoba | C14: dRe | D14: 20 | E14: 0 | F14: =D14*E14 -> 0 | H14: =D14*G14 -> 0 | I14: =1400/1.18 -> 1186.4407 | J14: =I14*D14 -> 23728.814 | K14: =F14+H14+J14 -> 23728.814
B15: jami | F15: =F14+F9 -> 0 | H15: =H14+H9 -> 0 | J15: =J14+J9 -> 138264.73 | K15: =K14+K9 -> 138264.73
B16: zednadebi xarji | C16: 0.074 | K16: =K15*C16 -> 10231.59
B17: jami | K17: =SUM(K15:K16) -> 148496.32
B18: yalibi | C18: 0.03 | K18: =K17*C18 -> 4454.8897
B19: jami | K19: =SUM(K17:K18) -> 152951.21
B20: teqnika | C20: 0.035 | K20: =K19*C20 -> 5353.2925
B21: jami | K21: =SUM(K19:K20) -> 158304.51
B22: mogeba | C22: 0.14 | K22: =K21*C22 -> 22162.631
B23: jami | K23: =SUM(K21:K22) -> 180467.14
B24: dRg | C24: 0.18 | K24: =K23*C24 -> 32484.085
B25: mTliani | K25: =SUM(K23:K24) -> 212951.22
A27: # | B27: samuSaos dasaxeleba | C27: gan/ba | D27: raod. | E27: masala, erT | F27: masala, sul | G27: xelf, erT | H27: xelf, sul | I27: moms. erT | J27: moms, sul | K27: jami
A28: 1 | B28: 2 | C28: 3 | D28: 4 | E28: 5 | F28: 6 | G28: 7 | H28: 8 | I28: 9 | J28: 10 | K28: 11
B29: konstruqciuli nawili
A30: 1 | B30: rkinabetonis karkasi | C30: m2 | D30: =D31 -> 7571.647 | E30: =SUM(F31:F42)/D30 -> 136.76513 | F30: =D30*E30 -> 1035537.3 | G30: =SUM(H31:H42)/D30 -> 64.800762 | H30: =D30*G30 -> 490648.5 | I30: =SUM(J31:J42)/D30 -> 7.4784269 | J30: =I30*D30 -> 56624.008 | K30: =F30+H30+J30 -> 1582809.8
B31: karkasis mowyoba | C31: m2 | D31: =სამუშაო!I111 -> 7571.647 | F31: 0 | G31: =ხელფასი!D3 -> 63.75 | H31: =D31*G31 -> 482692.5 | K31: =F31+H31+J31 -> 482692.5
B32: betoni b-7.5 | C32: m3 | D32: =117.5*1.02 -> 119.85 | E32: =მასალა!D5 -> 173.72881 | F32: =D32*E32 -> 20821.398 | H32: =D32*G32 -> 0 | I32: =1000/1.18 -> 847.45763 | J32: =I32*6 -> 5084.7458 | K32: =F32+H32+J32 -> 25906.144
B33: betoni b-25 | C33: m3 | D33: =1814.5*1.02 -> 1850.79 | E33: =მასალა!D6 -> 219.49153 | F33: =D33*E33 -> 406232.72 | H33: =D33*G33 -> 0 | K33: =F33+H33+J33 -> 406232.72
B34: Sveleris mowyoba | C34: grZ.m | D34: 312 | E34: =მასალა!D9 -> 98.305085 | F34: =D34*E34 -> 30671.186 | G34: =ხელფასი!D42 -> 25.5 | H34: =D34*G34 -> 7956 | I34: 8 | J34: =I34*D34 -> 2496 | K34: =F34+H34+J34 -> 41123.186
B35: liTonis furclis mowyoba | C35: grZ.m | D35: =(3.1*16+4.2*8+4*4)*1.1 -> 109.12 | E35: 0 | F35: =D35*E35 -> 0 | G35: 0 | H35: =D35*G35 -> 0 | I35: =მომსახურება!D27 -> 177.9661 | J35: =I35*D35+1500 -> 20919.661 | K35: =F35+H35+J35 -> 20919.661
B36: armatura a240 | C36: t | D36: =18.8*1.05 -> 19.74 | E36: =მასალა!$D$7 -> 1931.2271 | F36: =D36*E36 -> 38122.423 | H36: =D36*G36 -> 0 | K36: =F36+H36+J36 -> 38122.423
B37: armatura a500 | C37: t | D37: =217.275*1.05 -> 228.13875 | E37: =მასალა!$D$7 -> 1931.2271 | F37: =D37*E37 -> 440587.74 | H37: =D37*G37 -> 0 | K37: =F37+H37+J37 -> 440587.74
B38: Savi karkasis damxmare masala | C38: m2 | D38: =$D$31 -> 7571.647 | E38: =SUMIFS(მასალა!D3:D112,მასალა!B3:B112,ბიუჯეტი!B38) -> 10.169492 | F38: =D38*E38 -> 76999.8 | H38: =D38*G38 -> 0 | K38: =F38+H38+J38 -> 76999.8
B39: betonis Semowmeba kubikebiT | C39: cali | D39: =D33*0.15 -> 277.6185 | E39: 0 | F39: =D39*E39 -> 0 | H39: =D39*G39 -> 0 | I39: =მომსახურება!D26 -> 42.372881 | J39: =I39*D39 -> 11763.496 | K39: =F39+H39+J39 -> 11763.496
B40: geodeziuri momsaxureba | C40: cali | D40: 27 | E40: 0 | F40: =D40*E40 -> 0 | H40: =D40*G40 -> 0 | I40: =მომსახურება!D25 -> 466.10169 | J40: =I40*D40 -> 12584.746 | K40: =F40+H40+J40 -> 12584.746
B41: RorRi 10*20 | C41: m3 | D41: =64.5*15.8*0.12*1.02 -> 124.73784 | E41: =მასალა!D4 -> 38.135593 | F41: =D41*E41 -> 4756.9515 | H41: =G41*D41 -> 0 | I41: =7/1.18 -> 5.9322034 | J41: =I41*D41 -> 739.97024 | K41: =F41+H41+J41 -> 5496.9218
...

Sheet სამუშაო
A1: 20 iani bloki
A2: # | B2: niS.\ | C2: sarTuli | D2: fasadi | E2: sadarbazo | F2: binebis gamyofi | G2: ზღუდარი | H2: სარტყელი | I2: jami | J2: vada
A3: 1 | B3: 2 | C3: 3 | D3: 4 | E3: 5 | F3: 6 | G3: 7 | H3: 8 | I3: 9 | J3: 10
A4: 1 | B4: -2.3 | C4: 1 | D4: 0 | E4: 0 | F4: =((19.8+2+5.05+2.4+1.55+2.7+5.1+2.9+5.1+2.9+2.2+4.8+7.4+7+7+7.4+8.25)*2.32)*3 -> 651.108 | G4: 4 | H4: 3 | I4: =SUM(D4:H4) -> 658.108
A5: 2 | B5: 0 | C5: 2 | D5: =(((7+7+7+7+6.5+6.5+2.3+3.4+3.3)*2.6)+((4.4+3.5+1.1+1.6+3.5)*2.97))*2+(7+7+7+7+3.4+3.4+3.4+3.15+2.5)*2.6+(1.1+3.5+1.1+3.5+3.5+2+3.7+1+2+4.2)*2.97 -> 533.796 | E5: =((6.7+7+3.2+6.5+2.65+1.2)*2.97)*2+(7+7+6.9+2.9+2.6+1.2)*2.97 -> 243.837 | F5: =((6.7+0.8+7.9+2.7+7.4)*2.97)*2+((7+2.5+7.6)*2.97) -> 202.257 | G5: =11*1.5 -> 16.5 | H5: =3.5+3.5+4.4+3.4+3.4+4.4+3.5+3.5+3.5+3.7+4.2 -> 41 | I5: =SUM(D5:H5)-I15-D56+E56+F56*2.2 -> 917.83
A6: 3 | B6: 3.2 | C6: 3 | D6: =(((7+7+7+7+6.5+6.5+6.5+2.3+3.4)*2.6)+((4+1.1+2.8)*2.97))*2+(7+7+7+7+2.5+3.4+3.4+3.4+3.1)*2.6+(2.9+2.9+0.9+0.9+3.7+3.5+0.7+2.9)*2.97 -> 492.094 | E6: =((6.7+7+7+2.9+1.5+1.2)*2.97)*3 -> 234.333 | F6: =((3.2+2.2+3.8+7.7+2.7+7.4)*2.97)*2+((7+2.5+7.5)*2.97) -> 210.87 | G6: =11*1.5 -> 16.5 | H6: =3.5+3.5+4.4+4.4+3.5+3.5+3.5+2.4+3.7+4.2 -> 36.6 | I6: =SUM(D6:H6)-I17-D57+G57*2.2+25 -> 858.677
A7: 3 | B7: 6.4 | C7: 3 | D7: =(((7+7+7+7+6.5+6.5+6.5+2.3+3.4)*2.6)+((4+1.1+2.8)*2.97))*2+(7+7+7+7+2.5+3.4+3.4+3.4+3.1)*2.6+(2.9+2.9+0.9+0.9+3.7+3.5+0.7+2.9)*2.97 -> 492.094 | E7: =((6.7+7+7+2.9+1.5+1.2)*2.97)*3 -> 234.333 | F7: =((3.2+2.2+3.8+7.7+2.7+7.4)*2.97)*2+((7+2.5+7.5)*2.97) -> 210.87 | G7: =11*1.5 -> 16.5 | H7: =3.5+3.5+4.4+4.4+3.5+3.5+3.5+2.4+3.7+4.2 -> 36.6 | I7: =SUM(D7:H7)-I18-D58+G58*2.2+25 -> 858.677
A8: 4 | B8: 9.6 | C8: 4 | D8: =(((7+7+7+7+6.5+6.5+6.5+2.3+3.4)*2.6)+((4+1.1+2.8)*2.97))*2+(7+7+7+7+2.5+3.4+3.4+3.4+3.1)*2.6+(2.9+2.9+0.9+0.9+3.7+3.5+0.7+2.9)*2.97 -> 492.094 | E8: =((6.7+7+7+2.9+1.5+1.2)*2.97)*3 -> 234.333 | F8: =((3.2+2.2+3.8+7.7+2.7+7.4)*2.97)*2+((7+2.5+7.5)*2.97) -> 210.87 | G8: =11*1.5 -> 16.5 | H8: =3.5+3.5+4.4+4.4+3.5+3.5+3.5+2.4+3.7+4.2 -> 36.6 | I8: =SUM(D8:H8)-I18-D59+G59*2.2+25 -> 858.677
I9: =SUM(I4:I8) -> 4151.969 | J9: =SUM(J4:J8) -> 0
A11: m/plastmasi
A12: # | B12: niS.\ | C12: sarTuli | I12: jami | J12: vada
A13: 1 | B13: 2 | C13: 3 | D13: 4 | E13: 5 | F13: 6 | G13: 7 | H13: 8 | I13: 9 | J13: 10
A14: 1 | B14: -2.3 | C14: 1 | D14: =1.6*0.6*18 -> 17.28 | I14: =SUM(D14:H14) -> 17.28
A15: 2 | B15: 0 | C15: 2 | D15: =(1.6*1.6)*12+(1*1.6)*2+(1.6*2.6)*12+(1*2.6)*3+(1.7*2.6)*6 -> 118.16 | I15: =SUM(D15:H15) -> 118.16
A16: 2 | B16: 3.2 | C16: 2 | D16: =(1.6*1.6)*6+(1*1.6)*2+(1.6*2.6)*16+(1*2.6)*7+(1.7*2.6)*10+(1.2*2)*2 -> 152.32 | I16: =SUM(D16:H16) -> 152.32
A17: 3 | B17: 6.4 | C17: 3 | D17: =(1.6*1.6)*6+(1*1.6)*2+(1.6*2.6)*16+(1*2.6)*7+(1.7*2.6)*10+(1.2*2)*2 -> 152.32 | I17: =SUM(D17:H17) -> 152.32
A18: 4 | B18: 9.6 | C18: 4 | D18: =(1.6*1.6)*6+(1*1.6)*2+(1.6*2.6)*16+(1*2.6)*7+(1.7*2.6)*10+(1.2*2)*2 -> 152.32 | I18: =SUM(D18:H18) -> 152.32
I19: =SUM(I14:I18) -> 592.4 | J19: =SUM(J14:J18) -> 0
A21: fasadi
A22: # | B22: niS.\ | C22: sarTuli | D22: aguri | E22: daTbuneba/Rebva | F22: ferdili | G22: betonis faqtura | H22: bazalti | I22: jami | J22: vada
A23: 1 | B23: 2 | C23: 3 | D23: 4 | E23: 5 | F23: 6 | G23: 7 | H23: 8 | I23: 9 | J23: 10
A24: 1 | B24: -2.3 | C24: 1 | D24: 0 | F24: 0 | H24: =1.6*18 -> 28.8 | I24: =SUM(D24:H24) -> 28.8
A25: 2 | B25: 0 | C25: 2 | D25: 1072.18 | E25: =(2.2+2.2+2.5+1.3+3.8+1.3+4+2+1.8+3.4+1.6+1.1+2.9+2.2+2.2+2.5+1.3+3.8+1.3+4+2+1.8+3.4+1.6+1.1+2.9+2.6+1.1+2.6+1.1+3.5+3.8+1.25+1.15+2+2+2.9+2.4+2.2)*2.97 -> 263.736 | F25: =(15.4+15.4+2.65+5+1+2.7+2.7+5+2.7)+2.6*16+1.6*46+4*1+3.2*2+1.4*12+3*8 -> 218.95 | G25: 0 | H25: =1.7*14+1*2+3.1*3+3.2*3 -> 44.7 | I25: =SUM(D25:H25) -> 1599.566
A26: 3 | B26: 3.2 | C26: 3 | E26: =(4+2+2+2.9+0.9+0.4+4+2+2+2.9+0.9+0.4+2.9+2.2+2.1+2.9+0.9+0.4+0.8+3.5+0.9+3.1+3.7+2+1.8+2.9+0.9+0.4)*2.97 -> 165.726 | F26: =(2.3*2+1*6+2.6*32+1.6*32+3*8)*3 -> 507 | H26: =14*1.6+1*4+1.4*2 -> 29.2 | I26: =SUM(D26:H26) -> 701.926
A27: 4 | B27: 6.4 | C27: 4 | E27: =(4+2+2+2.9+0.9+0.4+4+2+2+2.9+0.9+0.4+2.9+2.2+2.1+2.9+0.9+0.4+0.8+3.5+0.9+3.1+3.7+2+1.8+2.9+0.9+0.4)*2.97 -> 165.726 | H27: =14*1.6+1*4+1.4*2 -> 29.2 | I27: =SUM(D27:H27) -> 194.926
A28: 5 | B28: 9.6 | C28: 5 | E28: =(4+2+2+2.9+0.9+0.4+4+2+2+2.9+0.9+0.4+2.9+2.2+2.1+2.9+0.9+0.4+0.8+3.5+0.9+3.1+3.7+2+1.8+2.9+0.9+0.4)*2.97 -> 165.726 | H28: =14*1.6+1*4+1.4*2 -> 29.2 | I28: =SUM(D28:H28) -> 194.926
C29: 6 | F29: 4 | I29: =SUM(D29:H29) -> 4
I30: =SUM(I24:I29) -> 2724.144 | J30: =SUM(J25:J28) -> 0
A32: 10 iani bloki
A33: # | B33: niS.\ | C33: sarTuli | D33: sadabazo | E33: aivani | F33: sak.Saxta binebi | G33: sak.Saxta sadarbazo | H33: tualeti | I33: jami | J33: vada
A34: 1 | B34: 2 | C34: 3 | D34: 4 | E34: 5 | F34: 6 | G34: 7 | H34: 8 | I34: 9 | J34: 10
A35: 1 | B35: -2.3 | C35: 1 | D35: =5.8*2.32 -> 13.456 | F35: =5.2*2.32 -> 12.064 | G35: 0 | H35: 0 | I35: =SUM(D35:H35) -> 25.52
A36: 2 | B36: 0 | C36: 2 | D36: 0 | E36: =(1.4+1.63+1.1+1.1+1.4+1.63)*2.97 -> 24.5322 | F36: =18.4*2.97 -> 54.648 | G36: =12.9*2.97 -> 38.313 | H36: 63.9 | I36: =SUM(D36:H36) -> 181.3932
A37: 2 | B37: 3.2 | C37: 3 | D37: 0 | E37: =(1.4+1.63+1.1+1.1+1.4+1.63)*2.97 -> 24.5322 | F37: =30.2*2.98 -> 89.996 | G37: =12.9*2.97 -> 38.313 | H37: 63.9 | I37: =SUM(D37:H37) -> 216.7412
A38: 3 | B38: 6.4 | C38: 4 | D38: 0 | E38: =(1.4+1.63+1.1+1.1+1.4+1.63)*2.97 -> 24.5322 | F38: =30.2*2.98 -> 89.996 | G38: =12.9*2.97 -> 38.313 | H38: 63.9 | I38: =SUM(D38:H38) -> 216.7412
A39: 4 | B39: 9.6 | C39: 5 | D39: 0 | E39: =(1.4+1.63+1.1+1.1+1.4+1.63)*2.97 -> 24.5322 | F39: =30.2*2.98 -> 89.996 | G39: =12.9*2.97 -> 38.313 | H39: 63.9 | I39: =SUM(D39:H39) -> 216.7412
I40: =SUM(I35:I39) -> 857.1368 | J40: =SUM(J35:J39) -> 0
A42: sadarbazo
A43: # | B43: niS.\ | C43: sarTuli | D43: lesva | E43: SefiTvna | F43: Rebva | G43: liftis aguri | H43: mdf | I43: jami | J43: vada
A44: 1 | B44: 2 | C44: 3 | D44: 4 | E44: 5 | F44: 6 | G44: 7 | H44: 8 | I44: 9 | J44: 10
...

Sheet მასალა
A1: # | B1: samuSaos dasaxeleba | C1: gan/ba | D1: masala, erT
A2: 1 | B2: 2 | C2: 3 | D2: 5
B3: inertuli masala | C3: m3 | D3: =40/1.18 -> 33.898305
B4: RorRi 10*20 | C4: m3 | D4: =45/1.18 -> 38.135593
B5: betoni b-7.5 | C5: m3 | D5: =205/1.18 -> 173.72881 | E5: გაძვირებულია წინა ბიუჯეტებში არ შეგვიცვლია
B6: betoni b-25 | C6: m3 | D6: =259/1.18 -> 219.49153
B7: armatura | C7: t | D7: =830*ფართები!E3/1.18 -> 1931.2271
B8: bloki 20-iani | C8: c | D8: =1.97/1.18 -> 1.6694915
B9: Sveleri 22 ni | C9: გრძ/მ | D9: =116/1.18 -> 98.305085
B10: qviSa | C10: m3 | D10: =70/1.18 -> 59.322034
B11: cementi m300 | C11: t | D11: =313.26/1.18 -> 265.47458
B12: aguri dekoratiuli | C12: cali | D12: =0.95/1.18 -> 0.80508475
B13: bazalti | C13: m2 | D13: =78/1.18 -> 66.101695
B14: Savi qviSa | C14: m3 | D14: =70/1.18 -> 59.322034
B15: bazaltis fila 03 | C15: m2 | D15: =70/1.18 -> 59.322034
B16: bazaltis fila 02 | C16: m2 | D16: =40/1.18 -> 33.898305
B17: bazaltis fila 05 | C17: m2 | D17: =140/1.18 -> 118.64407
B18: saRebavi | C18: litri | D18: =14.4/1.18 -> 12.20339
B19: kibis safexuri | C19: ცალი | D19: =140/1.18 -> 118.64407
B20: webo/cementi | C20: c | D20: =13/1.18 -> 11.016949
B21: meTlaxis fila | C21: მ2 | D21: =45/1.18 -> 38.135593 | E21: არსებული ფილები არღარ არის, ჩავსვი საორენტაციო ფასი
B22: fiTxi | C22: c | D22: =16.5/1.18 -> 13.983051
B23: bloki 10-iani | C23: c | D23: =1.25/1.18 -> 1.059322
B24: Tunuqi | C24: m2 | D24: =23/1.18 -> 19.491525
B25: membrana | C25: m2 | D25: =4/1.18 -> 3.3898305
B26: xis masala | C26: m3 | D26: =770/1.18 -> 652.54237
B27: xis dasamuSavebeli xsnari | C27: ლ | D27: =3.8/1.18 -> 3.220339
B28: milkvadrati 60*80 | C28: grZ.m | D28: =14.6/1.18 -> 12.372881
B29: iqspiesi | C29: m3 | D29: =8/1.18 -> 6.779661
B30: milkvadrati 100*100 | C30: grZ.m | D30: =21/1.18 -> 17.79661
B31: cementi m400 | C31: t | D31: =358.7/1.18 -> 303.98305
B32: T/muyaos fila | C32: c | D32: =14.9/1.18 -> 12.627119
B33: profili cd | C33: c | D33: =11.1/1.18 -> 9.4067797
B34: profili ud | C34: c | D34: =8.2/1.18 -> 6.9491525
B35: minabamba | C35: m2 | D35: =2.9/1.18 -> 2.4576271
B36: agrafi | C36: c | D36: =0.96/1.18 -> 0.81355932
B37: Surufi tn25 | C37: c | D37: =0.035/1.18 -> 0.029661017
B38: Surufi tn35 | C38: c | D38: =0.045/1.18 -> 0.038135593
B39: dubel Surufi k6 | C39: c | D39: =0.095/1.18 -> 0.080508475
B40: semiWka Surufi | C40: c | D40: =0.038/1.18 -> 0.03220339
...

Sheet მომსახურება
A1: # | B1: samuSaos dasaxeleba | C1: gan/ba | D1: Rirebuleba, erT
A2: 1 | B2: 2 | C2: 3 | D2: 5
B3: m/p kar-fanjara | C3: m2 | D3: =130*[1]ფართები!E2/1.18 -> 301.86441
B4: aluminis vitraJi | C4: m2 | D4: =160*ფართები!E3/1.18 -> 372.28475
B5: mdf-iT mowyoba | C5: m2 | D5: =230*1.27 -> 292.1
B6: kar-fanjrebis izolacia | C6: grZ.m | D6: =18/1.18 -> 15.254237
B7: iatakebis moWimva | C7: m2 | D7: =12/1.18 -> 10.169492
B8: liTonis binis kari | C8: cali | D8: =1300/1.18 -> 1101.6949
B9: სარდაფის kari | C9: cali | D9: =900/1.18 -> 762.71186
B10: saqvabis kari | C10: cali | D10: =1750/1.18 -> 1483.0508
B11: liTonis sadarbazos kari | C11: cali | D11: =3600/1.18 -> 3050.8475
B12: saxuravze gasasvleli gisosi | C12: cali | D12: =170/1.18 -> 144.0678
B13: liTonis kibis ujredis kari | C13: cali | D13: =1700/1.18 -> 1440.678
B14: liTonis aivnis moajiri | C14: grZ.m | D14: =260/1.18 -> 220.33898
B15: liTonis aivnis moajiri ცხაური | C15: მ2 | D15: =260/1.18 -> 220.33898
B16: liTonis kibis moajiri | C16: grZ.m | D16: =260/1.18 -> 220.33898
B17: liTonis kibis moajiri kedelze misamagrebeli | C17: grZ.m | D17: =85/1.18 -> 72.033898
B18: sakomunikacio liTonis kari xis dgarebiT | C18: cali | D18: =2000/1.18 -> 1694.9153
B19: ezos gamyofi xis tixrebi | C19: cali | D19: =1500/1.18 -> 1271.1864
B20: asaZromi kibe | C20: c | D20: =220/1.18 -> 186.44068
B21: lifti | C21: cali | D21: =(112425*[1]ფართები!E2/1.18)/2 -> 130527.33
B22: domofonis mowyoba | C22: bina | D22: =350/1.18 -> 296.61017
B23: internetis daqselva | C23: bina | D23: =160/1.18 -> 135.59322
B24: inertuli masalis tkepnis Semowmeba | C24: cali | D24: =50/1.18 -> 42.372881
B25: geodeziuri momsaxureba | C25: cali | D25: =550/1.18 -> 466.10169
B26: betonis kubikebis Semowmeba | C26: cali | D26: =50/1.18 -> 42.372881
B27: liTonis furclis mowyoba | C27: მ2 | D27: =210/1.18 -> 177.9661
B28: ინტერნეტის დაქსელვა | C28: მ2 | D28: =90/1.18 -> 76.271186
B29: samisamarTo saxanZro signalizaciis mowyoba | C29: სართული | D29: =5000/1.18 -> 4237.2881
B30: saxanZro mildgarebis sistemis mowyoba | C30: სართული | D30: =1300/1.18 -> 1101.6949
B31: saxanZro saventilacio danadgarebis mowyoba | C31: სართული | D31: =3400/1.18 -> 2881.3559
B32: tenti | C32: m2 | D32: =495/1.18 -> 419.49153
B33: wasasmeli hidroizolacia | C33: m2 | D33: =63/1.18 -> 53.389831

Sheet ხელფასი
A1: # | B1: samuSaos dasaxeleba | C1: gan/ba | D1: Rirebuleba, erT
A2: 1 | B2: 2 | C2: 3 | D2: 5
B3: რკინა ბეტონის მოწყობა | C3: მ2 | D3: =50*1.275 -> 63.75
B4: ბლოკი | C4: მ2 | D4: =1.5*1.275*12.5 -> 23.90625
B5: ზღუდარი | C5: გრძ/მ | D5: =15*1.275 -> 19.125
B6: სარტყელი | C6: გრძ/მ | D6: =35*1.275 -> 44.625
B7: აგური | C7: მ2 | D7: =65*1.275 -> 82.875
B8: aguris ferdili | C8: grZ.m | D8: =35*1.275 -> 44.625
B9: aguris cxauris mowyoba | C9: მ2 | D9: =120*1.275 -> 153
B10: bazaltis sacremlis mowyoba | C10: grZ.m | D10: =16*1.275 -> 20.4
B11: kar-fanjris ferdilebis amovseba | C11: cali | D11: =5*1.275 -> 6.375
B12: საცრემლის მოწყობა | C12: grZ.m | D12: =3*1.275 -> 3.825
B13: saxuravze Tunuqis mowyoba | C13: m2 | D13: =(23+25)*1.275 -> 61.2 | E13: მცირე მეწარმის გამო გაძვირდა, წინა პროექტებზე არ შევუცვალე
B14: mwvane saxuravis mowyoba | C14: m2 | D14: =26.5*1.275 -> 33.7875 | E14: მცირე მეწარმის გამო გაძვირდა, წინა პროექტებზე არ შევუცვალე
B15: k/granitis mowyoba | C15: m2 | D15: =30*1.275 -> 38.25
B16: k/granitis plintusis mowyoba | C16: grZ.m | D16: =10*1.275 -> 12.75
B17: bazaltis safexuris mowyoba | C17: cali | D17: =35*1.275 -> 44.625
B18: T/muyaos kedlis mowyoba | C18: m2 | D18: =12*1.275 -> 15.3
B19: T/muyaos tixris mowyoba | C19: m2 | D19: =16*1.275 -> 20.4
B20: gaTfobis milebis daqselva | C20: bina | D20: =130*1.275 -> 165.75
B21: kanalizaciis qselis mowyoba | C21: cali | D21: =25*1.275 -> 31.875
B22: kanalizaciis qselis mowyoba binaSi | C22: cali | D22: =45*1.275 -> 57.375
B23: ventilaciis qselis mowyoba | C23: cali | D23: =25*1.275 -> 31.875
B24: eleqtroobis mowyoba | C24: cali | D24: =8*1.275 -> 10.2
B25: aivnis sanaTis mowyoba | C25: cali | D25: =12*1.275 -> 15.3
B26: sadarbazos sanaTis mowyoba | C26: cali | D26: =45*1.275 -> 57.375
B27: Telasis kabelis mowyoba | C27: cali | D27: =45*1.275 -> 57.375
B28: sadarbazos daqselva | C28: grZ.m | D28: =3*1.275 -> 3.825
B29: wylis centraluri dgaris mowyoba | C29: grZ.m | D29: =20*1.275 -> 25.5
B30: wylis daqselva binebSi | C30: cali | D30: =(110+40)*1.275 -> 191.25
B31: kuTxovanis mowyoba | C31: grZ.m | D31: =10*1.275 -> 12.75
B32: kedlis gaxvreta kondincionerisTvis | C32: cali | D32: =10*1.275 -> 12.75
B33: Sida aivanze trapebis mowyoba | C33: cali | D33: =20*1.275 -> 25.5
B34: fasadis daTfuneba | C34: m2 | D34: =45*1.275 -> 57.375
B35: sadarbazos lesva | C35: m2 | D35: =18*1.275 -> 22.95
B36: SefiTxvna | C36: m2 | D36: =15*1.275 -> 19.125
B37: Rebva | C37: m2 | D37: =7*1.275 -> 8.925
B38: შავად ლესვა | C38: m2 | D38: =15*1.275 -> 19.125
B39: ეზოს სანიაღვრე ღარის მოწყობა | C39: გრძ/მ | D39: =50*1.275 -> 63.75
B40: კიბის საფეხურის მოწყობა | C40: ცალი | D40: =40*1.275 -> 51
...
