Workbook

Sheet ფართები
A1: lisi saxli - 6
B3: TariRi | C3: 45204 | D3: $ | E3: 2.6806
A5: # | B5: sarTuli | C5: samS. farTi | D5: sasarg. farTi | E5: %
A6: 1 | B6: 2 | C6: 3 | D6: 4 | E6: 5
A7: 1 | B7: saZirkveli | C7: =42*18 -> 756 | E7: =D7/C7 -> 0
A8: 2 | B8: 1 | C8: =42*18 -> 756 | D8: 556.8 | E8: =D8/C8 -> 0.73650794
A9: 3 | B9: 2 | C9: =41.8*17.7+1.6*4.4*2+6.5*1.2*2 -> 769.54 | D9: 638.4 | E9: =D9/C9 -> 0.82958651
A10: 4 | B10: 3 | C10: =41.8*17.7+1.6*4.4*6+6.5*1.2*2 -> 797.7 | D10: 638.4 | E10: =D10/C10 -> 0.80030086
A11: 5 | B11: 4 | C11: =41.8*17.7+1.6*4.4*6+6.5*1.2*2 -> 797.7 | D11: 638.4 | E11: =D11/C11 -> 0.80030086
A12: 6 | B12: saxuravi
B13: jami | C13: =SUM(C7:C12) -> 3876.94 | D13: =SUM(D7:D12) -> 2472 | E13: =D13/C13 -> 0.63761626
D17: 1ლ/m2 | E17: 1$/m2
A19: qvabuli | B19: =ბიუჯეტი!K25 -> 134603.96 | D19: =B19/C13 -> 34.719125 | E19: =D19/E3 -> 12.951998
A20: Savi karkasi | B20: =ბიუჯეტი!K57 -> 1542642.7 | D20: =B20/C13 -> 397.90212 | E20: =D20/E3 -> 148.43771
A21: TeTri karkasi | B21: =ბიუჯეტი!K481 -> 2657779.8 | D21: =B21/C13 -> 685.53546 | E21: =D21/E3 -> 255.73956
B22: =SUM(B20:B21) -> 4200422.5 | D22: =SUM(D19:D21) -> 1118.1567 | E22: =SUM(E19:E21) -> 417.12926
B23: =B22-[1]ფართები!$B$22 -> -218113.28

Sheet ბიუჯეტი
A1: q. TbilisSi, lisi
A2: sacxovrebeli saxlis winaswari xarjTaRricxva
A3: saxli #6
A4: xarjTaRricxva
I5: 45204
A6: # | B6: samuSaos dasaxeleba | C6: gan/ba | D6: raod. | E6: masala, erT | F6: masala, sul | G6: xelf, erT | H6: xelf, sul | I6: moms. erT | J6: moms, sul | K6: jami
A7: 1 | B7: 2 | C7: 3 | D7: 4 | E7: 5 | F7: 6 | G7: 7 | H7: 8 | I7: 9 | J7: 10 | K7: 11
B8: qvabulis samuSao
A9: 1 | B9: qvabulis mowyoba | C9: m2 | D9: =SUM(D10:D13) -> 3785.3125 | E9: =SUM(F10:F13)/D9 -> 0 | F9: =D9*E9 -> 0 | G9: 0 | H9: =D9*G9 -> 0 | I9: 18.7 | J9: =I9*D9 -> 70785.344 | K9: =F9+H9+J9 -> 70785.344
B10: qvabulis amoReba | C10: m3 | D10: =(46*20.5*2.7)*1.25 -> 3182.625 | E10: 0 | F10: 0 | G10: 0 | H10: =D10*G10 -> 0 | I10: 0 | J10: =I10*D10 -> 0 | K10: =F10+H10+J10 -> 0
B11: liftis Saxtis ormos amoReba | C11: m3 | D11: =(2.5*2.3*2.1*2)*1.25 -> 30.1875 | E11: 0 | F11: =D11*E11 -> 0 | G11: 0 | H11: =D11*G11 -> 0 | I11: 0 | J11: =I11*D11 -> 0 | K11: =F11+H11+J11 -> 0
B12: svetis ormos amoReba | C12: m3 | D12: =(2.5*2.5*2*26)*1.25 -> 406.25 | E12: 0 | F12: =D12*E12 -> 0 | G12: 0 | H12: =D12*G12 -> 0 | I12: 0 | J12: =I12*D12 -> 0 | K12: =F12+H12+J12 -> 0
B13: gverdiTa kedlebisTvis moWra | C13: m3 | D13: =(7*5*1.9*2)*1.25 -> 166.25 | E13: 0 | F13: =D13*E13 -> 0 | G13: 0 | H13: =D13*G13 -> 0 | I13: 0 | J13: =I13*D13 -> 0 | K13: =F13+H13+J13 -> 0
A14: 2 | B14: kodaliT muSaoba | C14: Tve | D14: 14 | E14: 0 | F14: =D14*E14 -> 0 | H14: =D14*G14 -> 0 | I14: =1400/1.18 -> 1186.4407 | J14: =I14*D14 -> 16610.169 | K14: =F14+H14+J14 -> 16610.169
B15: jami | F15: =F14+F9 -> 0 | H15: =H14+H9 -> 0 | J15: =J14+J9 -> 87395.513 | K15: =K14+K9 -> 87395.513
B16: zednadebi xarji | C16: 0.074 | K16: =K15*C16 -> 6467.268
B17: jami | K17: =SUM(K15:K16) -> 93862.781
B18: yalibi | C18: 0.03 | K18: =K17*C18 -> 2815.8834
B19: jami | K19: =SUM(K17:K18) -> 96678.665
B20: teqnika | C20: 0.035 | K20: =K19*C20 -> 3383.7533
B21: jami | K21: =SUM(K19:K20) -> 100062.42
B22: mogeba | C22: 0.14 | K22: =K21*C22 -> 14008.739
B23: jami | K23: =SUM(K21:K22) -> 114071.16
B24: dRg | C24: 0.18 | K24: =K23*C24 -> 20532.808
B25: mTliani | K25: =SUM(K23:K24) -> 134603.96
A27: # | B27: samuSaos dasaxeleba | C27: gan/ba | D27: raod. | E27: masala, erT | F27: masala, sul | G27: xelf, erT | H27: xelf, sul | I27: moms. erT | J27: moms, sul | K27: jami
A28: 1 | B28: 2 | C28: 3 | D28: 4 | E28: 5 | F28: 6 | G28: 7 | H28: 8 | I28: 9 | J28: 10 | K28: 11
B29: konstruqciuli nawili
A30: 1 | B30: rkinabetonis karkasi | C30: m2 | D30: =D31 -> 4750.01 | E30: =SUM(F31:F39)/D30 -> 133.44727 | F30: =D30*E30 -> 633875.85 | G30: =SUM(H31:H39)/D30 -> 52.507047 | H30: =D30*G30 -> 249409 | I30: =SUM(J31:J39)/D30 -> 1.3010091 | J30: =I30*D30 -> 6179.8061 | K30: =F30+H30+J30 -> 889464.65
B31: karkasis mowyoba | C31: m2 | D31: =ფართები!C13+26.25+43.12+356+119+88.2+176.4+33.4+16.2+14.5 -> 4750.01 | F31: 0 | G31: =40*1.275 -> 51 | H31: =D31*G31 -> 242250.51 | K31: =F31+H31+J31 -> 242250.51
B32: betoni b-7.5 | C32: m3 | D32: 40 | E32: =(170+9)/1.18 -> 151.69492 | F32: =D32*E32 -> 6067.7966 | H32: =D32*G32 -> 0 | K32: =F32+H32+J32 -> 6067.7966
B33: betoni b-25 | C33: m3 | D33: =(1050.42)*1.02 -> 1071.4284 | E33: =(230+9)/1.18 -> 202.54237 | F33: =D33*E33 -> 217009.65 | H33: =D33*G33 -> 0 | K33: =F33+H33+J33 -> 217009.65
B34: Sveleris mowyoba | C34: grZ.m | D34: 353 | E34: =116/1.18 -> 98.305085 | F34: =D34*E34 -> 34701.695 | G34: =15*1.275 -> 19.125 | H34: =D34*G34 -> 6751.125 | J34: =I34*D34 -> 0 | K34: =F34+H34+J34 -> 41452.82
B35: ლითონის ფურცლის მოწყობა | C35: grZ.m | D35: =7.1*3 -> 21.3 | E35: =225/1.18 -> 190.67797 | F35: =D35*E35 -> 4061.4407 | G35: =15*1.275 -> 19.125 | H35: =D35*G35 -> 407.3625 | J35: =I35*D35 -> 0 | K35: =F35+H35+J35 -> 4468.8032
B36: armatura a240 | C36: t | D36: 7.85 | E36: =850*ფართები!$E$3/1.18 -> 1930.9407 | F36: =D36*E36 -> 15157.884 | H36: =D36*G36 -> 0 | K36: =F36+H36+J36 -> 15157.884
B37: armatura a500 | C37: t | D37: =132.6*1.05 -> 139.23 | E37: =850*ფართები!$E$3/1.18 -> 1930.9407 | F37: =D37*E37 -> 268844.87 | H37: =D37*G37 -> 0 | K37: =F37+H37+J37 -> 268844.87
B38: damxmare masala | C38: m2 | D38: =$D$31 -> 4750.01 | E38: =12/1.18 -> 10.169492 | F38: =D38*E38 -> 48305.186 | H38: =D38*G38 -> 0 | K38: =F38+H38+J38 -> 48305.186
B39: inertuli masala | C39: m3 | D39: =((41*17.8*0.5)+(D11+D12))*1.3 -> 1041.7388 | E39: =45/1.18 -> 38.135593 | F39: =D39*E39 -> 39727.325 | H39: =G39*D39 -> 0 | I39: =7/1.18 -> 5.9322034 | J39: =I39*D39 -> 6179.8061 | K39: =F39+H39+J39 -> 45907.131
A40: 2 | B40: saZirkvlis betonis kedlebis hidroizolacia | C40: m2 | D40: =(41+18)*2 -> 118 | E40: =SUM(F41:F44)/D40 -> 38.221398 | F40: =D40*E40 -> 4510.125 | G40: =SUM(H41:H44)/D40 -> 10.2 | H40: =G40*D40 -> 1203.6 | I40: 0 | J40: =D40*I40 -> 0 | K40: =F40+H40+J40 -> 5713.725
B41: hidroizolacia | C41: m2 | D41: =D40 -> 118 | F41: =D41*E41 -> 0 | G41: =8*1.275 -> 10.2 | H41: =D41*G41 -> 1203.6 | J41: =D41*I41 -> 0 | K41: =F41+H41+J41 -> 1203.6
...

Sheet სამუშაო
A1: 20 iani bloki
A2: # | B2: niS.\ | C2: sarTuli | D2: fasadi | E2: sadarbazo | F2: binebis gamyofi | I2: jami | J2: vada
A3: 1 | B3: 2 | C3: 3 | D3: 4 | E3: 5 | F3: 6 | G3: 7 | H3: 8 | I3: 9 | J3: 10
A4: 1 | B4: 0 | C4: 1 | D4: 0 | E4: 0 | F4: =(6.5+6.5+3.1+1+6.65+6.65+1+5.9+1.2+2.85+5.9+1.2+2.85)*4.3 -> 220.59 | I4: =SUM(D4:H4) -> 220.59
A5: 2 | B5: 4.5 | C5: 2 | D5: =(6.5+6.5+3.1+6.5+6.5+3.2+1.8+3.4+3.2+1.8+3.4+6.5+6.5+6.5+3.1+6.5+6.5+6.5+6.5+6.5+6.5)*2.6 -> 279.5 | E5: =(7.25+7.25+6.5+3.1+2.9+2+3.8+1.65+5.9+3+1.55)*2.97*2 -> 266.706 | F5: =(5.14+1.45+6.5+6.25+5.05+6.5+3.1+6.5+5.05+6.25+1.45+6.5+5.05)*2.97 -> 192.4263 | I5: =SUM(D5:H5)-I14-I52*2.2 -> 583.8123
A6: 3 | B6: 7.7 | C6: 3 | D6: =((6.5*13)+6.2+3.2+1.8+3.4+3.2+1.8+3.4)*2.6 -> 279.5 | E6: =(6.5+7.05+2.9+3.8+1.35+1.5+5.9+3+1.35)*2.97*2 -> 198.099 | F6: =6.5*2.97*6+5*2.97*2+10.3*2.97+1.45*2.97*2+3.1*2.97 -> 193.941 | I6: =SUM(D6:H6)-I15-I53*2.2 -> 541.36
A7: 4 | B7: 10.9 | C7: 4 | D7: =((6.5*13)+6.2+3.2+1.8+3.4+3.2+1.8+3.4)*2.6 -> 279.5 | E7: =(6.5+7.05+2.9+3.8+1.35+1.5+5.9+3+1.35)*2.97*2 -> 198.099 | F7: =6.5*2.97*6+5*2.97*2+10.3*2.97+1.45*2.97*2+3.1*2.97 -> 193.941 | I7: =SUM(D7:H7)-I16-I54*2.2 -> 541.36
I8: =SUM(I4:I7) -> 1887.1223 | J8: =SUM(J4:J7) -> 0
A10: m/plastmasi
A11: # | B11: niS.\ | C11: sarTuli | I11: jami | J11: vada
A12: 1 | B12: 2 | C12: 3 | D12: 4 | E12: 5 | F12: 6 | G12: 7 | H12: 8 | I12: 9 | J12: 10
A13: 1 | B13: 0 | C13: 1 | D13: 0 | I13: =SUM(D13:H13) -> 0
A14: 2 | B14: 4.5 | C14: 2 | D14: =(1*2.6)*8+(1.6*2.6)*16+(1.6*1.6)*6+(2.5*2.5)*2 -> 115.22 | I14: =SUM(D14:H14) -> 115.22
A15: 3 | B15: 7.7 | C15: 3 | D15: =(1*2.6)*10+(1.6*2.6)*12+(1.6*1.6)*6+(2.5*2.5)*2 -> 103.78 | I15: =SUM(D15:H15) -> 103.78
A16: 4 | B16: 10.9 | C16: 4 | D16: =(1*2.6)*10+(1.6*2.6)*12+(1.6*1.6)*6+(2.5*2.5)*2 -> 103.78 | I16: =SUM(D16:H16) -> 103.78
I17: =SUM(I13:I16) -> 322.78 | J17: =SUM(J13:J16) -> 0
A19: fasadi
A20: # | B20: niS.\ | C20: sarTuli | D20: aguri | E20: daTbuneba/Rebva | F20: ferdili | G20: betonis faqtura | H20: bazalti | I20: jami | J20: vada
A21: 1 | B21: 2 | C21: 3 | D21: 4 | E21: 5 | F21: 6 | G21: 7 | H21: 8 | I21: 9 | J21: 10
A22: 1 | B22: -2.3 | C22: 1 | D22: 0 | I22: =SUM(D22:H22) -> 0
A23: 1 | B23: 0 | C23: 1 | D23: =(3.2*4.45)*2 -> 28.48 | E23: 0 | F23: 0 | G23: 0 | H23: =3.5*4+1.6*7 -> 25.2 | I23: =SUM(D23:H23) -> 53.68
A24: 2 | B24: 4.5 | C24: 2 | D24: =(17.8+17.8+1.7+0.7+1.4+3.2+3.2+3.2+1.4+0.7+1.7)*9.55+(11.35+11.35+14.4)*7.05+((1.6+0.9+0.2)*3)*6-156 -> 658.395 | E24: =42*2.6+(6.5+6.5+1.6+3.4+1.6+3.4)*2.98 -> 177.74 | F24: =(3.2*4)+(3*8)+(17.8+17.8+2.25+2+1.7) -> 78.35 | H24: =1.6*12+1*4 -> 23.2 | I24: =SUM(D24:H24) -> 937.685
A25: 3 | B25: 7.7 | C25: 3 | E25: =(6.5+6.5+1.6+3.4+1.6+3.4)*2.98 -> 68.54 | F25: =(1.6*26+1*6+2.6*32+3.2*4+3*8) -> 167.6 | H25: =1.6*12+1*4 -> 23.2 | I25: =SUM(D25:H25) -> 259.34
A26: 4 | B26: 10.9 | C26: 4 | E26: =(6.5+6.5+1.6+3.4+1.6+3.4)*2.98 -> 68.54 | F26: =(1.6*26+1*6+2.6*32+3.2*4+3*8) -> 167.6 | H26: =1.6*12+1*4 -> 23.2 | I26: =SUM(D26:H26) -> 259.34
C27: 5 | D27: =(17.85+17.85+17.5+17.5+11.3+11.3+14.4)*0.5 -> 53.85 | F27: =0.5*10 -> 5 | I27: =SUM(D27:H27) -> 58.85
I28: =SUM(I22:I27) -> 1568.895 | J28: =SUM(J23:J26) -> 0
A30: 10 iani bloki
A31: # | B31: niS.\ | C31: sarTuli | D31: sadabazo | E31: aivani | F31: sak.Saxta binebi | G31: sak.Saxta sadarbazo | H31: tualeti | I31: jami | J31: vada
A32: 1 | B32: 2 | C32: 3 | D32: 4 | E32: 5 | F32: 6 | G32: 7 | H32: 8 | I32: 9 | J32: 10
A33: 1 | B33: 0 | C33: 1 | F33: =21.6*4.3 -> 92.88 | G33: 0 | H33: =((2.8+1.4+2.85+3.2+1.16)*4.3)*2 -> 98.126 | I33: =SUM(D33:H33) -> 191.006
A34: 2 | B34: 4.5 | C34: 2 | D34: 0 | E34: =2.6*3.02*2 -> 15.704 | F34: =16.6*2.98 -> 49.468 | G34: =1.85*2*2.98 -> 11.026 | H34: =62.3*2.93-0.8*2.3*10 -> 164.139 | I34: =SUM(D34:H34) -> 240.337
A35: 3 | B35: 7.7 | C35: 3 | D35: =(2.9*2.98)*2 -> 17.284 | E35: =2.6*3.02*2 -> 15.704 | F35: =20.9*2.98 -> 62.282 | G35: =7.25*2.98 -> 21.605 | H35: =62.3*2.93-0.8*2.3*10 -> 164.139 | I35: =SUM(D35:H35) -> 281.014
A36: 4 | B36: 10.9 | C36: 4 | D36: =(2.9*2.98)*2 -> 17.284 | E36: =2.6*3.02*2 -> 15.704 | F36: =23.82*2.98 -> 70.9836 | G36: =9.75*2.98 -> 29.055 | H36: =62.3*2.93-0.8*2.3*10 -> 164.139 | I36: =SUM(D36:H36) -> 297.1656
I37: =SUM(I33:I36) -> 1009.5226 | J37: =SUM(J33:J36) -> 0
A39: sadarbazo
A40: # | B40: niS.\ | C40: sarTuli | D40: lesva | E40: SefiTvna | F40: Rebva | G40: liftis aguri | H40: mdf | I40: jami | J40: vada
A41: 1 | B41: 2 | C41: 3 | D41: 4 | E41: 5 | F41: 6 | G41: 7 | H41: 8 | I41: 9 | J41: 10
A42: 1 | B42: 0 | C42: 1 | D42: 0 | E42: 0 | F42: 0 | G42: 0 | H42: 0 | I42: =SUM(D42:H42) -> 0
A43: 2 | B43: 4.5 | C43: 2 | D43: =(57.9*2.98)*2-32.2 -> 312.884 | E43: =(57.9*2.98)*2 -> 345.084 | F43: =E43 -> 345.084 | G43: =0.75*2.97*4 -> 8.91 | H43: 19 | I43: =SUM(D43:H43) -> 1030.962
A44: 3 | B44: 7.7 | C44: 3 | D44: =(37.8*2.98)*2-2.3*12 -> 197.688 | E44: =(37.8*2.98)*2 -> 225.288 | F44: =E44 -> 225.288 | G44: =0.75*2.97*4 -> 8.91 | H44: 19 | I44: =SUM(D44:H44) -> 676.174
...
